2022-02-15 16:50:59,578 ERROR: Exception on /index [GET] [in C:\Users\Josh\.virtualenvs\flask_app-gvQn_Bzq\lib\site-packages\flask\app.py:1457]
Traceback (most recent call last):
  File "C:\Users\Josh\.virtualenvs\flask_app-gvQn_Bzq\lib\site-packages\flask\app.py", line 2073, in wsgi_app
    response = self.full_dispatch_request()
  File "C:\Users\Josh\.virtualenvs\flask_app-gvQn_Bzq\lib\site-packages\flask\app.py", line 1518, in full_dispatch_request
    rv = self.handle_user_exception(e)
  File "C:\Users\Josh\.virtualenvs\flask_app-gvQn_Bzq\lib\site-packages\flask\app.py", line 1516, in full_dispatch_request
    rv = self.dispatch_request()
  File "C:\Users\Josh\.virtualenvs\flask_app-gvQn_Bzq\lib\site-packages\flask\app.py", line 1502, in dispatch_request
    return self.ensure_sync(self.view_functions[rule.endpoint])(**req.view_args)
  File "C:\Users\Josh\.virtualenvs\flask_app-gvQn_Bzq\lib\site-packages\flask_login\utils.py", line 272, in decorated_view
    return func(*args, **kwargs)
  File "C:\Users\Josh\OneDrive - University of Bristol\Desktop\flask_app\app\routes.py", line 29, in index
    posts = current_user.followed_posts().paginate(
  File "C:\Users\Josh\OneDrive - University of Bristol\Desktop\flask_app\app\models.py", line 55, in followed_posts
    followers, (followers.c.followed_id == Post.user_id)).filter(
NameError: name 'followers' is not defined
2022-02-15 16:51:20,563 ERROR: Exception on /index [GET] [in C:\Users\Josh\.virtualenvs\flask_app-gvQn_Bzq\lib\site-packages\flask\app.py:1457]
Traceback (most recent call last):
  File "C:\Users\Josh\.virtualenvs\flask_app-gvQn_Bzq\lib\site-packages\flask\app.py", line 2073, in wsgi_app
    response = self.full_dispatch_request()
  File "C:\Users\Josh\.virtualenvs\flask_app-gvQn_Bzq\lib\site-packages\flask\app.py", line 1518, in full_dispatch_request
    rv = self.handle_user_exception(e)
  File "C:\Users\Josh\.virtualenvs\flask_app-gvQn_Bzq\lib\site-packages\flask\app.py", line 1516, in full_dispatch_request
    rv = self.dispatch_request()
  File "C:\Users\Josh\.virtualenvs\flask_app-gvQn_Bzq\lib\site-packages\flask\app.py", line 1502, in dispatch_request
    return self.ensure_sync(self.view_functions[rule.endpoint])(**req.view_args)
  File "C:\Users\Josh\.virtualenvs\flask_app-gvQn_Bzq\lib\site-packages\flask_login\utils.py", line 272, in decorated_view
    return func(*args, **kwargs)
  File "C:\Users\Josh\OneDrive - University of Bristol\Desktop\flask_app\app\routes.py", line 29, in index
    posts = current_user.followed_posts().paginate(
  File "C:\Users\Josh\OneDrive - University of Bristol\Desktop\flask_app\app\models.py", line 55, in followed_posts
    followers, (followers.c.followed_id == Post.user_id)).filter(
NameError: name 'followers' is not defined
2022-02-15 16:53:12,775 INFO: Microblog startup [in C:\Users\Josh\OneDrive - University of Bristol\Desktop\flask_app\app\__init__.py:43]
2022-02-15 16:53:16,748 ERROR: Exception on /index [GET] [in C:\Users\Josh\.virtualenvs\flask_app-gvQn_Bzq\lib\site-packages\flask\app.py:1457]
Traceback (most recent call last):
  File "C:\Users\Josh\.virtualenvs\flask_app-gvQn_Bzq\lib\site-packages\flask\app.py", line 2073, in wsgi_app
    response = self.full_dispatch_request()
  File "C:\Users\Josh\.virtualenvs\flask_app-gvQn_Bzq\lib\site-packages\flask\app.py", line 1518, in full_dispatch_request
    rv = self.handle_user_exception(e)
  File "C:\Users\Josh\.virtualenvs\flask_app-gvQn_Bzq\lib\site-packages\flask\app.py", line 1516, in full_dispatch_request
    rv = self.dispatch_request()
  File "C:\Users\Josh\.virtualenvs\flask_app-gvQn_Bzq\lib\site-packages\flask\app.py", line 1502, in dispatch_request
    return self.ensure_sync(self.view_functions[rule.endpoint])(**req.view_args)
  File "C:\Users\Josh\.virtualenvs\flask_app-gvQn_Bzq\lib\site-packages\flask_login\utils.py", line 272, in decorated_view
    return func(*args, **kwargs)
  File "C:\Users\Josh\OneDrive - University of Bristol\Desktop\flask_app\app\routes.py", line 29, in index
    posts = current_user.followed_posts().paginate(
  File "C:\Users\Josh\OneDrive - University of Bristol\Desktop\flask_app\app\models.py", line 54, in followed_posts
    followers, (followers.c.followed_id == Post.user_id)).filter(
NameError: name 'followers' is not defined
2022-02-15 16:55:34,052 INFO: Microblog startup [in C:\Users\Josh\OneDrive - University of Bristol\Desktop\flask_app\app\__init__.py:43]
2022-02-15 16:58:21,477 INFO: Microblog startup [in C:\Users\ACER\flask_app\app\__init__.py:43]
2022-02-15 17:19:22,430 INFO: Microblog startup [in C:\Users\ACER\flask_app\app\__init__.py:45]
2022-02-15 17:19:30,482 ERROR: Exception on /reset_password_request [GET] [in C:\Users\ACER\.pyenv\pyenv-win\versions\3.9.1\lib\site-packages\flask\app.py:1457]
Traceback (most recent call last):
  File "C:\Users\ACER\.pyenv\pyenv-win\versions\3.9.1\lib\site-packages\flask\app.py", line 2073, in wsgi_app
    response = self.full_dispatch_request()
  File "C:\Users\ACER\.pyenv\pyenv-win\versions\3.9.1\lib\site-packages\flask\app.py", line 1518, in full_dispatch_request
    rv = self.handle_user_exception(e)
  File "C:\Users\ACER\.pyenv\pyenv-win\versions\3.9.1\lib\site-packages\flask\app.py", line 1516, in full_dispatch_request
    rv = self.dispatch_request()
  File "C:\Users\ACER\.pyenv\pyenv-win\versions\3.9.1\lib\site-packages\flask\app.py", line 1502, in dispatch_request
    return self.ensure_sync(self.view_functions[rule.endpoint])(**req.view_args)
  File "C:\Users\ACER\flask_app\app\routes.py", line 177, in reset_password_request
    return render_template('reset_password_request.html',
  File "C:\Users\ACER\.pyenv\pyenv-win\versions\3.9.1\lib\site-packages\flask\templating.py", line 147, in render_template
    return _render(
  File "C:\Users\ACER\.pyenv\pyenv-win\versions\3.9.1\lib\site-packages\flask\templating.py", line 128, in _render
    rv = template.render(context)
  File "C:\Users\ACER\.pyenv\pyenv-win\versions\3.9.1\lib\site-packages\jinja2\environment.py", line 1291, in render
    self.environment.handle_exception()
  File "C:\Users\ACER\.pyenv\pyenv-win\versions\3.9.1\lib\site-packages\jinja2\environment.py", line 925, in handle_exception
    raise rewrite_traceback_stack(source=source)
  File "C:\Users\ACER\flask_app\app\templates\reset_password_request.html", line 1, in top-level template code
    {% extends "base.html" %}
  File "C:\Users\ACER\flask_app\app\templates\base.html", line 32, in top-level template code
    {% block content %}{% endblock %}
  File "C:\Users\ACER\flask_app\app\templates\reset_password_request.html", line 8, in block 'content'
    {{ form.password.label }}<br>
  File "C:\Users\ACER\.pyenv\pyenv-win\versions\3.9.1\lib\site-packages\jinja2\environment.py", line 474, in getattr
    return getattr(obj, attribute)
jinja2.exceptions.UndefinedError: 'app.forms.ResetPasswordRequestForm object' has no attribute 'password'
2022-02-15 17:20:49,449 INFO: Microblog startup [in C:\Users\ACER\flask_app\app\__init__.py:45]
2022-02-15 17:20:52,642 ERROR: Exception on /reset_password_request [GET] [in C:\Users\ACER\.pyenv\pyenv-win\versions\3.9.1\lib\site-packages\flask\app.py:1457]
Traceback (most recent call last):
  File "C:\Users\ACER\.pyenv\pyenv-win\versions\3.9.1\lib\site-packages\flask\app.py", line 2073, in wsgi_app
    response = self.full_dispatch_request()
  File "C:\Users\ACER\.pyenv\pyenv-win\versions\3.9.1\lib\site-packages\flask\app.py", line 1518, in full_dispatch_request
    rv = self.handle_user_exception(e)
  File "C:\Users\ACER\.pyenv\pyenv-win\versions\3.9.1\lib\site-packages\flask\app.py", line 1516, in full_dispatch_request
    rv = self.dispatch_request()
  File "C:\Users\ACER\.pyenv\pyenv-win\versions\3.9.1\lib\site-packages\flask\app.py", line 1502, in dispatch_request
    return self.ensure_sync(self.view_functions[rule.endpoint])(**req.view_args)
  File "C:\Users\ACER\flask_app\app\routes.py", line 177, in reset_password_request
    return render_template('reset_password_request.html',
  File "C:\Users\ACER\.pyenv\pyenv-win\versions\3.9.1\lib\site-packages\flask\templating.py", line 147, in render_template
    return _render(
  File "C:\Users\ACER\.pyenv\pyenv-win\versions\3.9.1\lib\site-packages\flask\templating.py", line 128, in _render
    rv = template.render(context)
  File "C:\Users\ACER\.pyenv\pyenv-win\versions\3.9.1\lib\site-packages\jinja2\environment.py", line 1291, in render
    self.environment.handle_exception()
  File "C:\Users\ACER\.pyenv\pyenv-win\versions\3.9.1\lib\site-packages\jinja2\environment.py", line 925, in handle_exception
    raise rewrite_traceback_stack(source=source)
  File "C:\Users\ACER\flask_app\app\templates\reset_password_request.html", line 1, in top-level template code
    {% extends "base.html" %}
  File "C:\Users\ACER\flask_app\app\templates\base.html", line 32, in top-level template code
    {% block content %}{% endblock %}
  File "C:\Users\ACER\flask_app\app\templates\reset_password_request.html", line 8, in block 'content'
    {{ form.password.label }}<br>
  File "C:\Users\ACER\.pyenv\pyenv-win\versions\3.9.1\lib\site-packages\jinja2\environment.py", line 474, in getattr
    return getattr(obj, attribute)
jinja2.exceptions.UndefinedError: 'app.forms.ResetPasswordRequestForm object' has no attribute 'password'
